Workbook

Sheet QA Checklist
A1: Area | B1: # | C1: Test Case | D1: Expected Result | E1: Status | F1: Notes
A2: 1. Auth — Login & Register | B2: 1 | C2: Register with valid data | D2: Auto-logged in, welcome toast shown, token present in localStorage | E2: Not Tested
B3: 2 | C3: Register with an email that already exists | D3: 409 error shown inline in the form, not silently swallowed | E3: Not Tested
B4: 3 | C4: Register with password under 6 characters | D4: Inline validation error, submission blocked | E4: Not Tested
B5: 4 | C5: Register with gender left unselected | D5: Inline validation error, submission blocked | E5: Not Tested
B6: 5 | C6: Register with malformed email | D6: Inline validation error, submission blocked | E6: Not Tested
B7: 6 | C7: Login with correct email, wrong password | D7: Generic 'Invalid email or password' error | E7: Not Tested
B8: 7 | C8: Login with non-existent email | D8: Generic 'Invalid email or password' error | E8: Not Tested
B9: 8 | C9: Login to a disabled account (is_active = 0) | D9: Login is rejected same as bad credentials | E9: Not Tested
B10: 9 | C10: Toggle 'Show password' in Login mode | D10: Password field switches between masked and plain text | E10: Not Tested
B11: 10 | C11: Toggle 'Show password' in Register mode | D11: Password field switches between masked and plain text | E11: Not Tested
B12: 11 | C12: Refresh page while logged in | D12: Session persists automatically (GET /auth/me.php runs on mount) | E12: Not Tested
B13: 12 | C13: Corrupt/expire the token in localStorage, then refresh | D13: Silently logged out, no crash, no stuck loading state | E13: Not Tested
B14: 13 | C14: Logout | D14: Success toast shown, token cleared, app still usable as anonymous | E14: Not Tested
A15: 2. Account Modal — Profile | B15: 1 | C15: Edit gender, then Cancel | D15: Value reverts, no API call made | E15: Not Tested
B16: 2 | C16: Edit gender, then Save | D16: Value persists after modal close/reopen and page refresh | E16: Not Tested
B17: 3 | C17: Trigger a gender save error (e.g. offline) | D17: Inline error message shown, form stays editable | E17: Not Tested
A18: 3. Account Modal — Change Password | B18: 1 | C18: Submit with wrong current password | D18: Server error shown inline, password not changed | E18: Not Tested
B19: 2 | C19: Submit with new password under 6 characters | D19: Client-side validation blocks submit before hitting API | E19: Not Tested
B20: 3 | C20: Submit with new/confirm password mismatched | D20: Client-side validation blocks submit before hitting API | E20: Not Tested
B21: 4 | C21: Submit a valid password change | D21: Success toast, form collapses/resets | E21: Not Tested
B22: 5 | C22: Log out and log back in with the new password | D22: Login succeeds with new password only | E22: Not Tested
B23: 6 | C23: Toggle 'Show passwords' inside the change-password form | D23: All three fields switch between masked and plain text together | E23: Not Tested
A24: 4. Account Modal — Manage Users (admin only) | B24: 1 | C24: Non-admin opens Account Modal | D24: 'Manage Users' section is not visible at all | E24: Not Tested
B25: 2 | C25: Admin expands 'Manage Users' | D25: List of users loads once; collapsing/re-expanding doesn't re-fetch needlessly | E25: Not Tested
B26: 3 | C26: Promote a normal user to admin | D26: Role badge updates immediately to 'Admin' | E26: Not Tested
B27: 4 | C27: Demote an admin back to member | D27: Role badge updates immediately to 'Member' | E27: Not Tested
B28: 5 | C28: Disable a user account | D28: 'Disabled' badge appears next to that row | E28: Not Tested
B29: 6 | C29: Re-enable a disabled account | D29: 'Disabled' badge disappears | E29: Not Tested
B30: 7 | C30: Confirm a disabled user genuinely cannot log in | D30: Login attempt fails for that account | E30: Not Tested
B31: 8 | C31: Check your own row in the list | D31: Promote/demote/disable buttons are absent for your own account | E31: Not Tested
A32: 5. Account Modal — Export (admin only) | B32: 1 | C32: Non-admin opens Account Modal | D32: 'Export services data (JSON)' link is not visible | E32: Not Tested
B33: 2 | C33: Admin clicks 'Export services data (JSON)' | D33: Browser downloads a service.json file | E33: Not Tested
B34: 3 | C34: Open the downloaded file | D34: Shape matches what createService() expects (id, name, category_id, tags, hours, etc.) | E34: Not Tested
A35: 6. Services CRUD (admin) | B35: 1 | C35: Add Service with name/category left blank | D35: Inline required-field errors, submission blocked | E35: Not Tested
B36: 2 | C36: Add Service with malformed phone | D36: Inline validation error (expects XXX-XXX-XXXX) | E36: Not Tested
B37: 3 | C37: Add Service with malformed email | D37: Inline validation error | E37: Not Tested
B38: 4 | C38: Add Service with latitude but no longitude (and vice versa) | D38: Inline validation error on the missing field | E38: Not Tested
B39: 5 | C39: Add Service with out-of-range latitude/longitude | D39: Inline validation error | E39: Not Tested
B40: 6 | C40: Add Service with an invalid Photo URL | D40: Inline validation error, no broken image shown | E40: Not Tested
...

Sheet Summary
A1: Area | B1: Total Tests | C1: Passed | D1: Failed | E1: Blocked | F1: Not Tested / N/A
A2: 1. Auth — Login & Register | B2: 13 | C2: =COUNTIFS('QA Checklist'!$E$2:$E$14,"Pass") -> 0 | D2: =COUNTIFS('QA Checklist'!$E$2:$E$14,"Fail") -> 0 | E2: =COUNTIFS('QA Checklist'!$E$2:$E$14,"Blocked") -> 0 | F2: =COUNTIFS('QA Checklist'!$E$2:$E$14,"Not Tested")+COUNTIFS('QA Checklist'!$E$2:$E$14,"N/A") -> 13
A3: 2. Account Modal — Profile | B3: 3 | C3: =COUNTIFS('QA Checklist'!$E$15:$E$17,"Pass") -> 0 | D3: =COUNTIFS('QA Checklist'!$E$15:$E$17,"Fail") -> 0 | E3: =COUNTIFS('QA Checklist'!$E$15:$E$17,"Blocked") -> 0 | F3: =COUNTIFS('QA Checklist'!$E$15:$E$17,"Not Tested")+COUNTIFS('QA Checklist'!$E$15:$E$17,"N/A") -> 3
A4: 3. Account Modal — Change Password | B4: 6 | C4: =COUNTIFS('QA Checklist'!$E$18:$E$23,"Pass") -> 0 | D4: =COUNTIFS('QA Checklist'!$E$18:$E$23,"Fail") -> 0 | E4: =COUNTIFS('QA Checklist'!$E$18:$E$23,"Blocked") -> 0 | F4: =COUNTIFS('QA Checklist'!$E$18:$E$23,"Not Tested")+COUNTIFS('QA Checklist'!$E$18:$E$23,"N/A") -> 6
A5: 4. Account Modal — Manage Users (admin only) | B5: 8 | C5: =COUNTIFS('QA Checklist'!$E$24:$E$31,"Pass") -> 0 | D5: =COUNTIFS('QA Checklist'!$E$24:$E$31,"Fail") -> 0 | E5: =COUNTIFS('QA Checklist'!$E$24:$E$31,"Blocked") -> 0 | F5: =COUNTIFS('QA Checklist'!$E$24:$E$31,"Not Tested")+COUNTIFS('QA Checklist'!$E$24:$E$31,"N/A") -> 8
A6: 5. Account Modal — Export (admin only) | B6: 3 | C6: =COUNTIFS('QA Checklist'!$E$32:$E$34,"Pass") -> 0 | D6: =COUNTIFS('QA Checklist'!$E$32:$E$34,"Fail") -> 0 | E6: =COUNTIFS('QA Checklist'!$E$32:$E$34,"Blocked") -> 0 | F6: =COUNTIFS('QA Checklist'!$E$32:$E$34,"Not Tested")+COUNTIFS('QA Checklist'!$E$32:$E$34,"N/A") -> 3
A7: 6. Services CRUD (admin) | B7: 16 | C7: =COUNTIFS('QA Checklist'!$E$35:$E$50,"Pass") -> 0 | D7: =COUNTIFS('QA Checklist'!$E$35:$E$50,"Fail") -> 0 | E7: =COUNTIFS('QA Checklist'!$E$35:$E$50,"Blocked") -> 0 | F7: =COUNTIFS('QA Checklist'!$E$35:$E$50,"Not Tested")+COUNTIFS('QA Checklist'!$E$35:$E$50,"N/A") -> 16
A8: 7. Recommendations — Public Submission | B8: 5 | C8: =COUNTIFS('QA Checklist'!$E$51:$E$55,"Pass") -> 0 | D8: =COUNTIFS('QA Checklist'!$E$51:$E$55,"Fail") -> 0 | E8: =COUNTIFS('QA Checklist'!$E$51:$E$55,"Blocked") -> 0 | F8: =COUNTIFS('QA Checklist'!$E$51:$E$55,"Not Tested")+COUNTIFS('QA Checklist'!$E$51:$E$55,"N/A") -> 5
A9: 8. Recommendations — Admin Moderation | B9: 6 | C9: =COUNTIFS('QA Checklist'!$E$56:$E$61,"Pass") -> 0 | D9: =COUNTIFS('QA Checklist'!$E$56:$E$61,"Fail") -> 0 | E9: =COUNTIFS('QA Checklist'!$E$56:$E$61,"Blocked") -> 0 | F9: =COUNTIFS('QA Checklist'!$E$56:$E$61,"Not Tested")+COUNTIFS('QA Checklist'!$E$56:$E$61,"N/A") -> 6
A10: 9. Reviews — Member Flow | B10: 4 | C10: =COUNTIFS('QA Checklist'!$E$62:$E$65,"Pass") -> 0 | D10: =COUNTIFS('QA Checklist'!$E$62:$E$65,"Fail") -> 0 | E10: =COUNTIFS('QA Checklist'!$E$62:$E$65,"Blocked") -> 0 | F10: =COUNTIFS('QA Checklist'!$E$62:$E$65,"Not Tested")+COUNTIFS('QA Checklist'!$E$62:$E$65,"N/A") -> 4
A11: 10. Reviews — Admin Moderation (per-service) | B11: 3 | C11: =COUNTIFS('QA Checklist'!$E$66:$E$68,"Pass") -> 0 | D11: =COUNTIFS('QA Checklist'!$E$66:$E$68,"Fail") -> 0 | E11: =COUNTIFS('QA Checklist'!$E$66:$E$68,"Blocked") -> 0 | F11: =COUNTIFS('QA Checklist'!$E$66:$E$68,"Not Tested")+COUNTIFS('QA Checklist'!$E$66:$E$68,"N/A") -> 3
A12: 11. Reviews — Admin 'Reviews' Tab (cross-listing) | B12: 5 | C12: =COUNTIFS('QA Checklist'!$E$69:$E$73,"Pass") -> 0 | D12: =COUNTIFS('QA Checklist'!$E$69:$E$73,"Fail") -> 0 | E12: =COUNTIFS('QA Checklist'!$E$69:$E$73,"Blocked") -> 0 | F12: =COUNTIFS('QA Checklist'!$E$69:$E$73,"Not Tested")+COUNTIFS('QA Checklist'!$E$69:$E$73,"N/A") -> 5
A13: 12. Search / Filters / Map | B13: 12 | C13: =COUNTIFS('QA Checklist'!$E$74:$E$85,"Pass") -> 0 | D13: =COUNTIFS('QA Checklist'!$E$74:$E$85,"Fail") -> 0 | E13: =COUNTIFS('QA Checklist'!$E$74:$E$85,"Blocked") -> 0 | F13: =COUNTIFS('QA Checklist'!$E$74:$E$85,"Not Tested")+COUNTIFS('QA Checklist'!$E$74:$E$85,"N/A") -> 12
A14: 13. Layout / UX | B14: 9 | C14: =COUNTIFS('QA Checklist'!$E$86:$E$94,"Pass") -> 0 | D14: =COUNTIFS('QA Checklist'!$E$86:$E$94,"Fail") -> 0 | E14: =COUNTIFS('QA Checklist'!$E$86:$E$94,"Blocked") -> 0 | F14: =COUNTIFS('QA Checklist'!$E$86:$E$94,"Not Tested")+COUNTIFS('QA Checklist'!$E$86:$E$94,"N/A") -> 9
A15: 14. Data Resilience | B15: 3 | C15: =COUNTIFS('QA Checklist'!$E$95:$E$97,"Pass") -> 0 | D15: =COUNTIFS('QA Checklist'!$E$95:$E$97,"Fail") -> 0 | E15: =COUNTIFS('QA Checklist'!$E$95:$E$97,"Blocked") -> 0 | F15: =COUNTIFS('QA Checklist'!$E$95:$E$97,"Not Tested")+COUNTIFS('QA Checklist'!$E$95:$E$97,"N/A") -> 3
A16: TOTAL | B16: =SUM(B2:B15) -> 96 | C16: =SUM(C2:C15) -> 0 | D16: =SUM(D2:D15) -> 0 | E16: =SUM(E2:E15) -> 0 | F16: =SUM(F2:F15) -> 96
